package org.zalando.planb.provider.exceptions;

import org.assertj.core.api.Assertions;
import org.junit.Test;
import org.springframework.beans.factory.annotation.Value;
import org.springframework.boot.test.SpringApplicationConfiguration;
import org.springframework.boot.test.WebIntegrationTest;
import org.springframework.http.RequestEntity;
import org.springframework.http.ResponseEntity;
import org.springframework.http.client.HttpComponentsClientHttpRequestFactory;
import org.springframework.test.context.ActiveProfiles;
import org.springframework.web.client.RestTemplate;
import org.zalando.planb.provider.AbstractSpringTest;
import org.zalando.planb.provider.Main;
import org.zalando.planb.provider.PassThroughResponseErrorHandler;

import java.net.URI;

@SpringApplicationConfiguration(classes = { Main.class })
@WebIntegrationTest(randomPort = true)
@ActiveProfiles("it")
public class ExceptionHandlingIT extends AbstractSpringTest {

    @Value("${local.server.port}")
    private int port;

    RestTemplate restTemplate = new RestTemplate(new HttpComponentsClientHttpRequestFactory());

    @Test
    public void error() {
        RequestEntity request = RequestEntity.get(URI.create("http://localhost:" + port + "/throwError")).build();
        restTemplate.setErrorHandler(new PassThroughResponseErrorHandler());
        ResponseEntity<String> response = restTemplate.exchange(request, String.class);
        Assertions.assertThat(response.getStatusCode().is5xxServerError()).isTrue();
        Assertions.assertThat(response.getBody()).contains("TEST_ERROR");
        Assertions.assertThat(response.getBody()).doesNotContain("Caused by");
    }

}
